<?xml version="1.0" encoding="utf-8"?>
<!-- This URDF was automatically created by SolidWorks to URDF Exporter! Originally created by Stephen Brawner (brawner@gmail.com) 
     Commit Version: 1.6.0-4-g7f85cfe  Build Version: 1.6.7995.38578
     For more information, please see http://wiki.ros.org/sw_urdf_exporter -->
<robot
  name="HandAssembly2">
  <link
    name="base_link">
    <inertial>
      <origin
        xyz="-0.0936672124273331 1.63489888294066E-10 0.535231939309104"
        rpy="0 0 0" />
      <mass
        value="279.343309739745" />
      <inertia
        ixx="34.9281247022782"
        ixy="-8.13293011493347E-09"
        ixz="-2.07006228380223"
        iyy="35.7141019454583"
        iyz="-2.13551764559151E-09"
        izz="12.2415875307062" />
    </inertial>
    <visual>
      <origin
        xyz="0 0 0"
        rpy="0 0 0" />
      <geometry>
        <mesh
          filename="package://HandAssembly2/meshes/base_link.STL" />
      </geometry>
      <material
        name="">
        <color
          rgba="0.792156862745098 0.819607843137255 0.933333333333333 1" />
      </material>
    </visual>
    <collision>
      <origin
        xyz="0 0 0"
        rpy="0 0 0" />
      <geometry>
        <mesh
          filename="package://HandAssembly2/meshes/base_link.STL" />
      </geometry>
    </collision>
  </link>
  <link
    name="finger_1">
    <inertial>
      <origin
        xyz="0.0582113837489129 4.16223523425074E-08 0.0400000490502332"
        rpy="0 0 0" />
      <mass
        value="2.62291219261925" />
      <inertia
        ixx="0.00599150094431563"
        ixy="2.04568885529465E-08"
        ixz="1.56227476550037E-08"
        iyy="0.0153590426966864"
        iyz="-1.69856752757802E-07"
        izz="0.0188065552886401" />
    </inertial>
    <visual>
      <origin
        xyz="0 0 0"
        rpy="0 0 0" />
      <geometry>
        <mesh
          filename="package://HandAssembly2/meshes/finger_1.STL" />
      </geometry>
      <material
        name="">
        <color
          rgba="0.792156862745098 0.819607843137255 0.933333333333333 1" />
      </material>
    </visual>
    <collision>
      <origin
        xyz="0 0 0"
        rpy="0 0 0" />
      <geometry>
        <mesh
          filename="package://HandAssembly2/meshes/finger_1.STL" />
      </geometry>
    </collision>
  </link>
  <joint
    name="fin1"
    type="revolute">
    <origin
      xyz="0.308639953146409 0.175 1.22256279986678"
      rpy="3.14159265358979 -0.582486579623969 0" />
    <parent
      link="base_link" />
    <child
      link="finger_1" />
    <axis
      xyz="0 0 1" />
    <limit
      lower="0"
      upper="2"
      effort="0"
      velocity="0" />
  </joint>
  <link
    name="finger_1_1">
    <inertial>
      <origin
        xyz="0.0912178205801498 0.0600876616121566 5.31188101282609E-08"
        rpy="0 0 0" />
      <mass
        value="2.39970051632588" />
      <inertia
        ixx="0.00825497807923866"
        ixy="-0.00491198632784708"
        ixz="3.89380816170649E-08"
        iyy="0.0124760376603049"
        iyz="2.83949164129252E-08"
        izz="0.0126583434717946" />
    </inertial>
    <visual>
      <origin
        xyz="0 0 0"
        rpy="0 0 0" />
      <geometry>
        <mesh
          filename="package://HandAssembly2/meshes/finger_1_1.STL" />
      </geometry>
      <material
        name="">
        <color
          rgba="0.792156862745098 0.819607843137255 0.933333333333333 1" />
      </material>
    </visual>
    <collision>
      <origin
        xyz="0 0 0"
        rpy="0 0 0" />
      <geometry>
        <mesh
          filename="package://HandAssembly2/meshes/finger_1_1.STL" />
      </geometry>
    </collision>
  </link>
  <joint
    name="fin1_1"
    type="revolute">
    <origin
      xyz="0.179528059776071 0 0.0399996964134806"
      rpy="-1.5707963267949 -0.582486579623969 0" />
    <parent
      link="finger_1" />
    <child
      link="finger_1_1" />
    <axis
      xyz="-4.99498279141106E-05 -3.29033596607708E-05 -0.999999998211192" />
    <limit
      lower="0"
      upper="2"
      effort="0"
      velocity="0" />
  </joint>
  <link
    name="finger_1_1_1">
    <inertial>
      <origin
        xyz="0.0527784328799715 0.0347666892791179 -4.97915925157244E-09"
        rpy="0 0 0" />
      <mass
        value="1.21959091463891" />
      <inertia
        ixx="0.00266721626156747"
        ixy="0.0001999689611466"
        ixz="8.56502520871384E-10"
        iyy="0.00249537578748383"
        iyz="5.75549595692808E-10"
        izz="0.00235597916354427" />
    </inertial>
    <visual>
      <origin
        xyz="0 0 0"
        rpy="0 0 0" />
      <geometry>
        <mesh
          filename="package://HandAssembly2/meshes/finger_1_1_1.STL" />
      </geometry>
      <material
        name="">
        <color
          rgba="0.792156862745098 0.819607843137255 0.933333333333333 1" />
      </material>
    </visual>
    <collision>
      <origin
        xyz="0 0 0"
        rpy="0 0 0" />
      <geometry>
        <mesh
          filename="package://HandAssembly2/meshes/finger_1_1_1.STL" />
      </geometry>
    </collision>
  </link>
  <joint
    name="fin1_1_1"
    type="revolute">
    <origin
      xyz="0.204435726444991 0.134667212398081 0"
      rpy="0 0 0" />
    <parent
      link="finger_1_1" />
    <child
      link="finger_1_1_1" />
    <axis
      xyz="4.99498279133785E-05 3.29033596622835E-05 0.999999998211192" />
    <limit
      lower="0"
      upper="2"
      effort="0"
      velocity="0" />
  </joint>
  <link
    name="finger_1_eef">
    <inertial>
      <origin
        xyz="0.0188171286265765 -4.97915925157244E-09 -0.0123954210124275"
        rpy="0 0 0" />
      <mass
        value="1.21959091463891" />
      <inertia
        ixx="0.00266721626156747"
        ixy="8.56502520840658E-10"
        ixz="-0.0001999689611466"
        iyy="0.00235597916354427"
        iyz="-5.75549595673798E-10"
        izz="0.00249537578748383" />
    </inertial>
    <visual>
      <origin
        xyz="0 0 0"
        rpy="0 0 0" />
      <geometry>
        <mesh
          filename="package://HandAssembly2/meshes/finger_1_eef.STL" />
      </geometry>
      <material
        name="">
        <color
          rgba="0.792156862745098 0.819607843137255 0.933333333333333 1" />
      </material>
    </visual>
    <collision>
      <origin
        xyz="0 0 0"
        rpy="0 0 0" />
      <geometry>
        <mesh
          filename="package://HandAssembly2/meshes/finger_1_eef.STL" />
      </geometry>
    </collision>
  </link>
  <joint
    name="fin1_eef"
    type="fixed">
    <origin
      xyz="0.0339613042533951 0.0223712682666903 0"
      rpy="1.5707963267949 0 0" />
    <parent
      link="finger_1_1_1" />
    <child
      link="finger_1_eef" />
    <axis
      xyz="0 0 0" />
  </joint>
  <link
    name="finger_2">
    <inertial>
      <origin
        xyz="0.0582113997401505 7.2059313627193E-08 0.0399998347308492"
        rpy="0 0 0" />
      <mass
        value="2.62291216939469" />
      <inertia
        ixx="0.0059916892852438"
        ixy="2.54236843542384E-08"
        ixz="-6.34236507668275E-08"
        iyy="0.0153587785697811"
        iyz="-1.788387632831E-07"
        izz="0.0188064904153421" />
    </inertial>
    <visual>
      <origin
        xyz="0 0 0"
        rpy="0 0 0" />
      <geometry>
        <mesh
          filename="package://HandAssembly2/meshes/finger_2.STL" />
      </geometry>
      <material
        name="">
        <color
          rgba="0.792156862745098 0.819607843137255 0.933333333333333 1" />
      </material>
    </visual>
    <collision>
      <origin
        xyz="0 0 0"
        rpy="0 0 0" />
      <geometry>
        <mesh
          filename="package://HandAssembly2/meshes/finger_2.STL" />
      </geometry>
    </collision>
  </link>
  <joint
    name="fin2"
    type="revolute">
    <origin
      xyz="0.382548654972508 0 0.780508398722002"
      rpy="3.14159265358979 0.436413643527903 0" />
    <parent
      link="base_link" />
    <child
      link="finger_2" />
    <axis
      xyz="0 0 1" />
    <limit
      lower="0"
      upper="2"
      effort="0"
      velocity="0" />
  </joint>
  <link
    name="finger_2_1">
    <inertial>
      <origin
        xyz="0.0989920974591484 -0.0461705253229426 2.04530046454821E-07"
        rpy="0 0 0" />
      <mass
        value="2.39969352647452" />
      <inertia
        ixx="0.00692962504514686"
        ixy="0.00409591270353601"
        ixz="-1.42185073855786E-09"
        iyy="0.0138012038593891"
        iyz="2.47784668845037E-09"
        izz="0.012658197491362" />
    </inertial>
    <visual>
      <origin
        xyz="0 0 0"
        rpy="0 0 0" />
      <geometry>
        <mesh
          filename="package://HandAssembly2/meshes/finger_2_1.STL" />
      </geometry>
      <material
        name="">
        <color
          rgba="0.792156862745098 0.819607843137255 0.933333333333333 1" />
      </material>
    </visual>
    <collision>
      <origin
        xyz="0 0 0"
        rpy="0 0 0" />
      <geometry>
        <mesh
          filename="package://HandAssembly2/meshes/finger_2_1.STL" />
      </geometry>
    </collision>
  </link>
  <joint
    name="fin2_1"
    type="revolute">
    <origin
      xyz="0.179528059776071 0 0.0399996964134798"
      rpy="-1.5707963267949 0.436413643527903 0" />
    <parent
      link="finger_2" />
    <child
      link="finger_2_1" />
    <axis
      xyz="0 0 -1" />
    <limit
      lower="0"
      upper="2"
      effort="0"
      velocity="0" />
  </joint>
  <link
    name="finger_2_1_1">
    <inertial>
      <origin
        xyz="0.0572767994330114 -0.0267141823562029 -5.92834292767463E-09"
        rpy="0 0 0" />
      <mass
        value="1.21958916107902" />
      <inertia
        ixx="0.00272116821091193"
        ixy="-0.000166746141068283"
        ixz="9.19142199931018E-10"
        iyy="0.00244142078028996"
        iyz="-4.11542290661205E-10"
        izz="0.00235597934140297" />
    </inertial>
    <visual>
      <origin
        xyz="0 0 0"
        rpy="0 0 0" />
      <geometry>
        <mesh
          filename="package://HandAssembly2/meshes/finger_2_1_1.STL" />
      </geometry>
      <material
        name="">
        <color
          rgba="0.792156862745098 0.819607843137255 0.933333333333333 1" />
      </material>
    </visual>
    <collision>
      <origin
        xyz="0 0 0"
        rpy="0 0 0" />
      <geometry>
        <mesh
          filename="package://HandAssembly2/meshes/finger_2_1_1.STL" />
      </geometry>
    </collision>
  </link>
  <joint
    name="fin2_1_1"
    type="revolute">
    <origin
      xyz="0.221859646346035 -0.103477155282569 0"
      rpy="0 0 0" />
    <parent
      link="finger_2_1" />
    <child
      link="finger_2_1_1" />
    <axis
      xyz="0 0 1" />
    <limit
      lower="0"
      upper="2"
      effort="0"
      velocity="0" />
  </joint>
  <link
    name="finger_2_eef">
    <inertial>
      <origin
        xyz="0.0204209447278962 -5.92834292767463E-09 0.00952436547505686"
        rpy="0 0 0" />
      <mass
        value="1.21958916107902" />
      <inertia
        ixx="0.00272116821091193"
        ixy="9.19142199913752E-10"
        ixz="0.000166746141068283"
        iyy="0.00235597934140297"
        iyz="4.11542290652494E-10"
        izz="0.00244142078028996" />
    </inertial>
    <visual>
      <origin
        xyz="0 0 0"
        rpy="0 0 0" />
      <geometry>
        <mesh
          filename="package://HandAssembly2/meshes/finger_2_eef.STL" />
      </geometry>
      <material
        name="">
        <color
          rgba="0.792156862745098 0.819607843137255 0.933333333333333 1" />
      </material>
    </visual>
    <collision>
      <origin
        xyz="0 0 0"
        rpy="0 0 0" />
      <geometry>
        <mesh
          filename="package://HandAssembly2/meshes/finger_2_eef.STL" />
      </geometry>
    </collision>
  </link>
  <joint
    name="fin2_eef"
    type="fixed">
    <origin
      xyz="0.0368558547051152 -0.0171898168811461 0"
      rpy="1.5707963267949 0 0" />
    <parent
      link="finger_2_1_1" />
    <child
      link="finger_2_eef" />
    <axis
      xyz="0 0 0" />
  </joint>
  <link
    name="finger_3">
    <inertial>
      <origin
        xyz="0.0582113837489122 4.16223523425074E-08 0.0400000490502328"
        rpy="0 0 0" />
      <mass
        value="2.62291219261925" />
      <inertia
        ixx="0.00599150094431563"
        ixy="2.04568885804952E-08"
        ixz="1.56227476632437E-08"
        iyy="0.0153590426966865"
        iyz="-1.69856752748938E-07"
        izz="0.0188065552886401" />
    </inertial>
    <visual>
      <origin
        xyz="0 0 0"
        rpy="0 0 0" />
      <geometry>
        <mesh
          filename="package://HandAssembly2/meshes/finger_3.STL" />
      </geometry>
      <material
        name="">
        <color
          rgba="0.792156862745098 0.819607843137255 0.933333333333333 1" />
      </material>
    </visual>
    <collision>
      <origin
        xyz="0 0 0"
        rpy="0 0 0" />
      <geometry>
        <mesh
          filename="package://HandAssembly2/meshes/finger_3.STL" />
      </geometry>
    </collision>
  </link>
  <joint
    name="fin3"
    type="revolute">
    <origin
      xyz="0.308639953146409 -0.175 1.22256279986678"
      rpy="3.14159265358979 -0.58248657962397 0" />
    <parent
      link="base_link" />
    <child
      link="finger_3" />
    <axis
      xyz="0 0 1" />
    <limit
      lower="0"
      upper="2"
      effort="0"
      velocity="0" />
  </joint>
  <link
    name="finger_3_1">
    <inertial>
      <origin
        xyz="0.0912178521377192 0.0600876536370687 1.96832685261938E-07"
        rpy="0 0 0" />
      <mass
        value="2.39970180172285" />
      <inertia
        ixx="0.00825494009821537"
        ixy="-0.00491196249837052"
        ixz="-1.70357329426909E-10"
        iyy="0.0124759980503085"
        iyz="3.797673696491E-10"
        izz="0.0126583003760249" />
    </inertial>
    <visual>
      <origin
        xyz="0 0 0"
        rpy="0 0 0" />
      <geometry>
        <mesh
          filename="package://HandAssembly2/meshes/finger_3_1.STL" />
      </geometry>
      <material
        name="">
        <color
          rgba="0.792156862745098 0.819607843137255 0.933333333333333 1" />
      </material>
    </visual>
    <collision>
      <origin
        xyz="0 0 0"
        rpy="0 0 0" />
      <geometry>
        <mesh
          filename="package://HandAssembly2/meshes/finger_3_1.STL" />
      </geometry>
    </collision>
  </link>
  <joint
    name="fin3_1"
    type="revolute">
    <origin
      xyz="0.179528059776071 0 0.03999969641348"
      rpy="-1.5707963267949 -0.58248657962397 0" />
    <parent
      link="finger_3" />
    <child
      link="finger_3_1" />
    <axis
      xyz="0 0 -1" />
    <limit
      lower="0"
      upper="2"
      effort="0"
      velocity="0" />
  </joint>
  <link
    name="finger_3_1_1">
    <inertial>
      <origin
        xyz="0.0527784333270103 0.0347666897140826 -4.9791595291282E-09"
        rpy="0 0 0" />
      <mass
        value="1.21959090651552" />
      <inertia
        ixx="0.00266721492952682"
        ixy="0.000199970654460971"
        ixz="1.4638102712091E-09"
        iyy="0.00249537312667758"
        iyz="9.90432843642849E-10"
        izz="0.0023559755663535" />
    </inertial>
    <visual>
      <origin
        xyz="0 0 0"
        rpy="0 0 0" />
      <geometry>
        <mesh
          filename="package://HandAssembly2/meshes/finger_3_1_1.STL" />
      </geometry>
      <material
        name="">
        <color
          rgba="0.792156862745098 0.819607843137255 0.933333333333333 1" />
      </material>
    </visual>
    <collision>
      <origin
        xyz="0 0 0"
        rpy="0 0 0" />
      <geometry>
        <mesh
          filename="package://HandAssembly2/meshes/finger_3_1_1.STL" />
      </geometry>
    </collision>
  </link>
  <joint
    name="fin3_1_1"
    type="fixed">
    <origin
      xyz="0.20443572644499 0.13466721239808 0"
      rpy="0 0 0" />
    <parent
      link="finger_3_1" />
    <child
      link="finger_3_1_1" />
    <axis
      xyz="0 0 1" />
    <limit
      lower="0"
      upper="2"
      effort="0"
      velocity="0" />
  </joint>
  <link
    name="finger_3_eef">
    <inertial>
      <origin
        xyz="0.0188171290736152 -4.9791595291282E-09 -0.0123954214473923"
        rpy="0 0 0" />
      <mass
        value="1.21959090651552" />
      <inertia
        ixx="0.00266721492952682"
        ixy="1.46381027119326E-09"
        ixz="-0.000199970654460971"
        iyy="0.0023559755663535"
        iyz="-9.90432843631924E-10"
        izz="0.00249537312667758" />
    </inertial>
    <visual>
      <origin
        xyz="0 0 0"
        rpy="0 0 0" />
      <geometry>
        <mesh
          filename="package://HandAssembly2/meshes/finger_3_eef.STL" />
      </geometry>
      <material
        name="">
        <color
          rgba="0.792156862745098 0.819607843137255 0.933333333333333 1" />
      </material>
    </visual>
    <collision>
      <origin
        xyz="0 0 0"
        rpy="0 0 0" />
      <geometry>
        <mesh
          filename="package://HandAssembly2/meshes/finger_3_eef.STL" />
      </geometry>
    </collision>
  </link>
  <joint
    name="fin3_eef"
    type="fixed">
    <origin
      xyz="0.0339613042533951 0.0223712682666903 0"
      rpy="1.5707963267949 0 0" />
    <parent
      link="finger_3_1_1" />
    <child
      link="finger_3_eef" />
    <axis
      xyz="0 0 0" />
  </joint>
</robot>