<?xml version="1.0" encoding="utf-8"?>
<!-- This URDF was automatically created by SolidWorks to URDF Exporter! Originally created by Stephen Brawner (brawner@gmail.com) 
     Commit Version: 1.6.0-4-g7f85cfe  Build Version: 1.6.7995.38578
     For more information, please see http://wiki.ros.org/sw_urdf_exporter -->
<robot
  name="hand">
  <link
    name="base_link">
    <inertial>
      <origin
        xyz="-0.0936672124273331 1.63489888294066E-10 0.535231939309103"
        rpy="0 0 0" />
      <mass
        value="279.343309739745" />
      <inertia
        ixx="34.9281247022782"
        ixy="-8.13293010180577E-09"
        ixz="-2.07006228380223"
        iyy="35.7141019454583"
        iyz="-2.13551763091779E-09"
        izz="12.2415875307062" />
    </inertial>
    <visual>
      <origin
        xyz="0 0 0"
        rpy="0 0 0" />
      <geometry>
        <mesh
          filename="package://dexterous/meshes/base_link.STL" />
      </geometry>
      <material
        name="">
        <color
          rgba="0.792156862745098 0.819607843137255 0.933333333333333 1" />
      </material>
    </visual>
    <collision>
      <origin
        xyz="0 0 0"
        rpy="0 0 0" />
      <geometry>
        <mesh
          filename="package://dexterous/meshes/base_link.STL" />
      </geometry>
    </collision>
  </link>
  <link
    name="finger_1">
    <inertial>
      <origin
        xyz="0.0582113837489122 4.16223521204628E-08 0.0400000490502329"
        rpy="0 0 0" />
      <mass
        value="2.62291219261926" />
      <inertia
        ixx="0.00599150094431569"
        ixy="2.04568885344446E-08"
        ixz="1.56227476747362E-08"
        iyy="0.0153590426966866"
        iyz="-1.69856752756128E-07"
        izz="0.0188065552886403" />
    </inertial>
    <visual>
      <origin
        xyz="0 0 0"
        rpy="0 0 0" />
      <geometry>
        <mesh
          filename="package://dexterous/meshes/finger_1.STL" />
      </geometry>
      <material
        name="">
        <color
          rgba="0.792156862745098 0.819607843137255 0.933333333333333 1" />
      </material>
    </visual>
    <collision>
      <origin
        xyz="0 0 0"
        rpy="0 0 0" />
      <geometry>
        <mesh
          filename="package://dexterous/meshes/finger_1.STL" />
      </geometry>
    </collision>
  </link>
  <joint
    name="fin1"
    type="revolute">
    <origin
      xyz="0.308639953146409 0.175 1.22256279986678"
      rpy="3.14159265358979 -0.582486579623969 0" />
    <parent
      link="base_link" />
    <child
      link="finger_1" />
    <axis
      xyz="0 0 1" />
    <limit
      lower="-1"
      upper="1"
      effort="0"
      velocity="0" />
  </joint>
  <link
    name="finger_1_1">
    <inertial>
      <origin
        xyz="0.0912174387332344 0.0600874065867316 2.78205906034668E-07"
        rpy="0 0 0" />
      <mass
        value="2.39969138530032" />
      <inertia
        ixx="0.00825489500630393"
        ixy="-0.00491190228357168"
        ixz="-2.00018381331709E-08"
        iyy="0.0124758879394617"
        iyz="-1.14992762721286E-08"
        izz="0.0126581634000926" />
    </inertial>
    <visual>
      <origin
        xyz="0 0 0"
        rpy="0 0 0" />
      <geometry>
        <mesh
          filename="package://dexterous/meshes/finger_1_1.STL" />
      </geometry>
      <material
        name="">
        <color
          rgba="0.792156862745098 0.819607843137255 0.933333333333333 1" />
      </material>
    </visual>
    <collision>
      <origin
        xyz="0 0 0"
        rpy="0 0 0" />
      <geometry>
        <mesh
          filename="package://dexterous/meshes/finger_1_1.STL" />
      </geometry>
    </collision>
  </link>
  <joint
    name="fin1_1"
    type="revolute">
    <origin
      xyz="0.179528059776071 0 0.0399996964134806"
      rpy="-1.5707963267949 -0.582486579623969 0" />
    <parent
      link="finger_1" />
    <child
      link="finger_1_1" />
    <axis
      xyz="-4.99498279141106E-05 -3.29033596607708E-05 -0.999999998211192" />
    <limit
      lower="0"
      upper="2"
      effort="0"
      velocity="0" />
  </joint>
  <link
    name="finger_1_1_1">
    <inertial>
      <origin
        xyz="0.0527784322758119 0.0347666889774279 -4.76739692167882E-09"
        rpy="0 0 0" />
      <mass
        value="1.2195909202896" />
      <inertia
        ixx="0.00266721627307185"
        ixy="0.00019996895051314"
        ixz="8.82126930819854E-10"
        iyy="0.00249537581218203"
        iyz="5.93373254535351E-10"
        izz="0.00235597919144712" />
    </inertial>
    <visual>
      <origin
        xyz="0 0 0"
        rpy="0 0 0" />
      <geometry>
        <mesh
          filename="package://dexterous/meshes/finger_1_1_1.STL" />
      </geometry>
      <material
        name="">
        <color
          rgba="0.792156862745098 0.819607843137255 0.933333333333333 1" />
      </material>
    </visual>
    <collision>
      <origin
        xyz="0 0 0"
        rpy="0 0 0" />
      <geometry>
        <mesh
          filename="package://dexterous/meshes/finger_1_1_1.STL" />
      </geometry>
    </collision>
  </link>
  <joint
    name="fin1_1_1"
    type="revolute">
    <origin
      xyz="0.204435726444991 0.134667212398081 0"
      rpy="0 0 0" />
    <parent
      link="finger_1_1" />
    <child
      link="finger_1_1_1" />
    <axis
      xyz="4.99498279133785E-05 3.29033596622835E-05 0.999999998211192" />
    <limit
      lower="-2"
      upper="0"
      effort="0"
      velocity="0" />
  </joint>
  <link
    name="finger_1_eef">
    <inertial>
      <origin
        xyz="0.0188171280224169 -4.76739692167882E-09 -0.0123954207107375"
        rpy="0 0 0" />
      <mass
        value="1.2195909202896" />
      <inertia
        ixx="0.00266721627307185"
        ixy="8.82126930789128E-10"
        ixz="-0.00019996895051314"
        iyy="0.00235597919144712"
        iyz="-5.93373254516341E-10"
        izz="0.00249537581218203" />
    </inertial>
    <visual>
      <origin
        xyz="0 0 0"
        rpy="0 0 0" />
      <geometry>
        <mesh
          filename="package://dexterous/meshes/finger_1_eef.STL" />
      </geometry>
      <material
        name="">
        <color
          rgba="0.792156862745098 0.819607843137255 0.933333333333333 1" />
      </material>
    </visual>
    <collision>
      <origin
        xyz="0 0 0"
        rpy="0 0 0" />
      <geometry>
        <mesh
          filename="package://dexterous/meshes/finger_1_eef.STL" />
      </geometry>
    </collision>
  </link>
  <joint
    name="fin1_eef"
    type="fixed">
    <origin
      xyz="0.0339613042533951 0.0223712682666903 0"
      rpy="1.5707963267949 0 0" />
    <parent
      link="finger_1_1_1" />
    <child
      link="finger_1_eef" />
    <axis
      xyz="0 0 0" />
  </joint>
  <link
    name="finger_2">
    <inertial>
      <origin
        xyz="0.0582113997401504 7.20593135161707E-08 0.0399998347308493"
        rpy="0 0 0" />
      <mass
        value="2.62291216939468" />
      <inertia
        ixx="0.00599168928524379"
        ixy="2.54236843800562E-08"
        ixz="-6.34236507683454E-08"
        iyy="0.015358778569781"
        iyz="-1.78838763283497E-07"
        izz="0.0188064904153421" />
    </inertial>
    <visual>
      <origin
        xyz="0 0 0"
        rpy="0 0 0" />
      <geometry>
        <mesh
          filename="package://dexterous/meshes/finger_2.STL" />
      </geometry>
      <material
        name="">
        <color
          rgba="0.792156862745098 0.819607843137255 0.933333333333333 1" />
      </material>
    </visual>
    <collision>
      <origin
        xyz="0 0 0"
        rpy="0 0 0" />
      <geometry>
        <mesh
          filename="package://dexterous/meshes/finger_2.STL" />
      </geometry>
    </collision>
  </link>
  <joint
    name="fin2"
    type="revolute">
    <origin
      xyz="0.382548654972508 0 0.780508398722002"
      rpy="3.14159265358979 0.436413643527903 0" />
    <parent
      link="base_link" />
    <child
      link="finger_2" />
    <axis
      xyz="0 0 1" />
    <limit
      lower="-1"
      upper="1"
      effort="0"
      velocity="0" />
  </joint>
  <link
    name="finger_2_1">
    <inertial>
      <origin
        xyz="0.0989919072013307 -0.0461704453918806 2.80457902568365E-07"
        rpy="0 0 0" />
      <mass
        value="2.39968898922773" />
      <inertia
        ixx="0.00692960842888985"
        ixy="0.00409589220427107"
        ixz="-2.11861548475042E-08"
        iyy="0.0138011469966554"
        iyz="1.07269708711359E-08"
        izz="0.0126581396998082" />
    </inertial>
    <visual>
      <origin
        xyz="0 0 0"
        rpy="0 0 0" />
      <geometry>
        <mesh
          filename="package://dexterous/meshes/finger_2_1.STL" />
      </geometry>
      <material
        name="">
        <color
          rgba="0.792156862745098 0.819607843137255 0.933333333333333 1" />
      </material>
    </visual>
    <collision>
      <origin
        xyz="0 0 0"
        rpy="0 0 0" />
      <geometry>
        <mesh
          filename="package://dexterous/meshes/finger_2_1.STL" />
      </geometry>
    </collision>
  </link>
  <joint
    name="fin2_1"
    type="revolute">
    <origin
      xyz="0.179528059776071 0 0.0399996964134798"
      rpy="-1.5707963267949 0.436413643527903 0" />
    <parent
      link="finger_2" />
    <child
      link="finger_2_1" />
    <axis
      xyz="0 0 -1" />
    <limit
      lower="-2"
      upper="0"
      effort="0"
      velocity="0" />
  </joint>
  <link
    name="finger_2_1_1">
    <inertial>
      <origin
        xyz="0.0572767994330112 -0.0267141823562029 -5.92834314971924E-09"
        rpy="0 0 0" />
      <mass
        value="1.21958916107902" />
      <inertia
        ixx="0.00272116821091195"
        ixy="-0.000166746141068286"
        ixz="9.1914220049119E-10"
        iyy="0.00244142078028997"
        iyz="-4.11542290988672E-10"
        izz="0.00235597934140298" />
    </inertial>
    <visual>
      <origin
        xyz="0 0 0"
        rpy="0 0 0" />
      <geometry>
        <mesh
          filename="package://dexterous/meshes/finger_2_1_1.STL" />
      </geometry>
      <material
        name="">
        <color
          rgba="0.792156862745098 0.819607843137255 0.933333333333333 1" />
      </material>
    </visual>
    <collision>
      <origin
        xyz="0 0 0"
        rpy="0 0 0" />
      <geometry>
        <mesh
          filename="package://dexterous/meshes/finger_2_1_1.STL" />
      </geometry>
    </collision>
  </link>
  <joint
    name="fin2_1_1"
    type="revolute">
    <origin
      xyz="0.221859646346035 -0.103477155282569 0"
      rpy="0 0 0" />
    <parent
      link="finger_2_1" />
    <child
      link="finger_2_1_1" />
    <axis
      xyz="0 0 1" />
    <limit
      lower="0"
      upper="2"
      effort="0"
      velocity="0" />
  </joint>
  <link
    name="finger_2_eef">
    <inertial>
      <origin
        xyz="0.020420944727896 -5.92834314971924E-09 0.00952436547505686"
        rpy="0 0 0" />
      <mass
        value="1.21958916107902" />
      <inertia
        ixx="0.00272116821091195"
        ixy="9.1914220047405E-10"
        ixz="0.000166746141068286"
        iyy="0.00235597934140298"
        iyz="4.11542290979969E-10"
        izz="0.00244142078028997" />
    </inertial>
    <visual>
      <origin
        xyz="0 0 0"
        rpy="0 0 0" />
      <geometry>
        <mesh
          filename="package://dexterous/meshes/finger_2_eef.STL" />
      </geometry>
      <material
        name="">
        <color
          rgba="0.792156862745098 0.819607843137255 0.933333333333333 1" />
      </material>
    </visual>
    <collision>
      <origin
        xyz="0 0 0"
        rpy="0 0 0" />
      <geometry>
        <mesh
          filename="package://dexterous/meshes/finger_2_eef.STL" />
      </geometry>
    </collision>
  </link>
  <joint
    name="fin2_eef"
    type="fixed">
    <origin
      xyz="0.0368558547051152 -0.0171898168811461 0"
      rpy="1.5707963267949 0 0" />
    <parent
      link="finger_2_1_1" />
    <child
      link="finger_2_eef" />
    <axis
      xyz="0 0 0" />
  </joint>
  <link
    name="finger_3">
    <inertial>
      <origin
        xyz="0.0582113837489122 4.16223523425074E-08 0.0400000490502331"
        rpy="0 0 0" />
      <mass
        value="2.62291219261926" />
      <inertia
        ixx="0.00599150094431568"
        ixy="2.04568885529867E-08"
        ixz="1.56227476534859E-08"
        iyy="0.0153590426966865"
        iyz="-1.69856752755103E-07"
        izz="0.0188065552886402" />
    </inertial>
    <visual>
      <origin
        xyz="0 0 0"
        rpy="0 0 0" />
      <geometry>
        <mesh
          filename="package://dexterous/meshes/finger_3.STL" />
      </geometry>
      <material
        name="">
        <color
          rgba="0.792156862745098 0.819607843137255 0.933333333333333 1" />
      </material>
    </visual>
    <collision>
      <origin
        xyz="0 0 0"
        rpy="0 0 0" />
      <geometry>
        <mesh
          filename="package://dexterous/meshes/finger_3.STL" />
      </geometry>
    </collision>
  </link>
  <joint
    name="fin3"
    type="revolute">
    <origin
      xyz="0.308639953146409 -0.175 1.22256279986678"
      rpy="3.14159265358979 -0.58248657962397 0" />
    <parent
      link="base_link" />
    <child
      link="finger_3" />
    <axis
      xyz="0 0 1" />
    <limit
      lower="-1"
      upper="1"
      effort="0"
      velocity="0" />
  </joint>
  <link
    name="finger_3_1">
    <inertial>
      <origin
        xyz="0.091217438733235 0.060087406586731 2.78205906534268E-07"
        rpy="0 0 0" />
      <mass
        value="2.39969138530032" />
      <inertia
        ixx="0.00825489500630393"
        ixy="-0.00491190228357168"
        ixz="-2.00018381498108E-08"
        iyy="0.0124758879394616"
        iyz="-1.14992762793102E-08"
        izz="0.0126581634000926" />
    </inertial>
    <visual>
      <origin
        xyz="0 0 0"
        rpy="0 0 0" />
      <geometry>
        <mesh
          filename="package://dexterous/meshes/finger_3_1.STL" />
      </geometry>
      <material
        name="">
        <color
          rgba="0.792156862745098 0.819607843137255 0.933333333333333 1" />
      </material>
    </visual>
    <collision>
      <origin
        xyz="0 0 0"
        rpy="0 0 0" />
      <geometry>
        <mesh
          filename="package://dexterous/meshes/finger_3_1.STL" />
      </geometry>
    </collision>
  </link>
  <joint
    name="fin3_1"
    type="revolute">
    <origin
      xyz="0.179528059776071 0 0.03999969641348"
      rpy="-1.5707963267949 -0.58248657962397 0" />
    <parent
      link="finger_3" />
    <child
      link="finger_3_1" />
    <axis
      xyz="0 0 -1" />
    <limit
      lower="0"
      upper="2"
      effort="0"
      velocity="0" />
  </joint>
  <link
    name="finger_3_1_1">
    <inertial>
      <origin
        xyz="0.0527784322758127 0.0347666889774283 -4.76739669963422E-09"
        rpy="0 0 0" />
      <mass
        value="1.21959092028959" />
      <inertia
        ixx="0.00266721497330702"
        ixy="0.000199970605801"
        ixz="1.48943468103907E-09"
        iyy="0.00249537319047578"
        iyz="1.00825650294165E-09"
        izz="0.00235597566360135" />
    </inertial>
    <visual>
      <origin
        xyz="0 0 0"
        rpy="0 0 0" />
      <geometry>
        <mesh
          filename="package://dexterous/meshes/finger_3_1_1.STL" />
      </geometry>
      <material
        name="">
        <color
          rgba="0.792156862745098 0.819607843137255 0.933333333333333 1" />
      </material>
    </visual>
    <collision>
      <origin
        xyz="0 0 0"
        rpy="0 0 0" />
      <geometry>
        <mesh
          filename="package://dexterous/meshes/finger_3_1_1.STL" />
      </geometry>
    </collision>
  </link>
  <joint
    name="fin3_1_1"
    type="revolute">
    <origin
      xyz="0.20443572644499 0.13466721239808 0"
      rpy="0 0 0" />
    <parent
      link="finger_3_1" />
    <child
      link="finger_3_1_1" />
    <axis
      xyz="0 0 -1" />
    <limit
      lower="0"
      upper="2"
      effort="0"
      velocity="0" />
  </joint>
  <link
    name="finger_3_eef">
    <inertial>
      <origin
        xyz="0.0188171280224176 -4.76739669963422E-09 -0.012395420710738"
        rpy="0 0 0" />
      <mass
        value="1.21959092028959" />
      <inertia
        ixx="0.00266721497330702"
        ixy="1.48943468102324E-09"
        ixz="-0.000199970605801"
        iyy="0.00235597566360135"
        iyz="-1.00825650293072E-09"
        izz="0.00249537319047578" />
    </inertial>
    <visual>
      <origin
        xyz="0 0 0"
        rpy="0 0 0" />
      <geometry>
        <mesh
          filename="package://dexterous/meshes/finger_3_eef.STL" />
      </geometry>
      <material
        name="">
        <color
          rgba="0.792156862745098 0.819607843137255 0.933333333333333 1" />
      </material>
    </visual>
    <collision>
      <origin
        xyz="0 0 0"
        rpy="0 0 0" />
      <geometry>
        <mesh
          filename="package://dexterous/meshes/finger_3_eef.STL" />
      </geometry>
    </collision>
  </link>
  <joint
    name="fin3_eef"
    type="fixed">
    <origin
      xyz="0.0339613042533951 0.0223712682666903 0"
      rpy="1.5707963267949 0 0" />
    <parent
      link="finger_3_1_1" />
    <child
      link="finger_3_eef" />
    <axis
      xyz="0 0 0" />
  </joint>
</robot>